Workbook

Sheet Summary
B1: USB PERFORMANCE TEST REPORT — BLANK TEMPLATE
B2: Project: ______________________ Date: ______________
B3: Device under test: model, name and firmware — fill in the Devices Under Test table below.
B5: OVERALL RESULT | D5: ROUNDS RUN | F5: PASSED | H5: FAILED | J5: SKIPPED | L5: PASS RATE
B6: =IF(D6+J6=0,"NO DATA",IF(H6>0,"FAIL",IF(J6>0,"INCOMPLETE","PASS"))) -> NO DATA | D6: =COUNTA(Results!$N$5:$N$5004)-COUNTIF(Results!$N$5:$N$5004,"SKIPPED") -> 0 | F6: =COUNTIF(Results!$N$5:$N$5004,"PASS") -> 0 | H6: =D6-F6 -> 0 | J6: =COUNTIF(Results!$N$5:$N$5004,"SKIPPED") -> 0 | L6: =IFERROR(F6/D6,"–") -> –
B8: AVG READ | E8: AVG WRITE | H8: PEAK READ | K8: PEAK WRITE
B9: =IFERROR(AVERAGEIFS(Results!$H$5:$H$5004,Results!$E$5:$E$5004,"read",Results!$I$5:$I$5004,">0"),"–") -> – | E9: =IFERROR(AVERAGEIFS(Results!$H$5:$H$5004,Results!$E$5:$E$5004,"write",Results!$I$5:$I$5004,">0"),"–") -> – | H9: =IF(COUNTIFS(Results!$E$5:$E$5004,"read")=0,"–",SUMPRODUCT(MAX((Results!$E$5:$E$5004="read")*Results!$H$5:$H$5004))) -> – | K9: =IF(COUNTIFS(Results!$E$5:$E$5004,"write")=0,"–",SUMPRODUCT(MAX((Results!$E$5:$E$5004="write")*Results!$H$5:$H$5004))) -> –
B72: TEST ENVIRONMENT
B73: Project | H73: Client
B74: Test date | H74: Client IP
B75: Topology | H75: Rounds per case
B76: Connection | H76: Interfaces tested
B77: PC network link | H77: Log file
B78: Test file set
B79: Pass thresholds
B81: DEVICES UNDER TEST
B82: Role | C82: Name | E82: Model | G82: Firmware | K82: HW Version | L82: USB Share
B83: Router
B84: Extender

Sheet Results
A1: TEST RESULTS — DETAILED DATA
A2: Use the arrows on the header row to filter or sort. Time, SSID, BSSID, firmware and other traceability columns are grouped — click the [+] above 'Failure Reason' to show them.
A3: TEST CASE | H3: MEASUREMENT | N3: RESULT
A4: DUT Role | B4: Interface | C4: Connection | D4: USB Format | E4: Direction | F4: File | G4: Round | H4: Throughput (MB/s) | I4: Duration (s) | J4: Average (MB/s) | K4: Min (MB/s) | L4: Max (MB/s) | M4: Std Dev | N4: Result | O4: Failure Reason | P4: Time | Q4: USB Share | R4: SSID | S4: Actual Band | T4: Channel | U4: Signal | V4: BSSID | W4: Client IP | X4: Gateway IP | Y4: File Check | Z4: File Set | AA4: Detected USB Format | AB4: DUT Model | AC4: DUT Name | AD4: Firmware | AE4: HW Version | AF4: Topology | AG4: Client Type | AH4: Client OS | AI4: Project | AJ4: Interface Matched | AK4: Role Assumed | AL4: DUT Reachable | AM4: Share Writable

Sheet Issues
A1: FAILED, SKIPPED AND ABNORMAL CASES
A2: List failed, skipped or abnormal rounds here (or filter the Results sheet by Result).
A4: Result | B4: DUT Role | C4: Interface | D4: USB Format | E4: Direction | F4: File | G4: Round | H4: Reason

Sheet Analysis
A1: ANALYSIS — THE NUMBERS BEHIND THE CHARTS
A2: Every value is a formula reading the Results sheet. Change a label in the first column to analyse a different value.
A4: BY INTERFACE — wired port speed or wireless band
A5: Interface | B5: Rounds Run | C5: Passed | D5: Failed | E5: Skipped | F5: Pass Rate | G5: Avg Read (MB/s) | H5: Avg Write (MB/s)
A6: 1Gbps | B6: =COUNTIFS(Results!$B$5:$B$5004,$A6,Results!$N$5:$N$5004,"<>SKIPPED") -> 0 | C6: =COUNTIFS(Results!$B$5:$B$5004,$A6,Results!$N$5:$N$5004,"PASS") -> 0 | D6: =B6-C6 -> 0 | E6: =COUNTIFS(Results!$B$5:$B$5004,$A6,Results!$N$5:$N$5004,"SKIPPED") -> 0 | F6: =IFERROR(C6/B6,"–") -> – | G6: =IFERROR(AVERAGEIFS(Results!$H$5:$H$5004,Results!$B$5:$B$5004,$A6,Results!$E$5:$E$5004,"read",Results!$I$5:$I$5004,">0"),"–") -> – | H6: =IFERROR(AVERAGEIFS(Results!$H$5:$H$5004,Results!$B$5:$B$5004,$A6,Results!$E$5:$E$5004,"write",Results!$I$5:$I$5004,">0"),"–") -> –
A7: 2.5Gbps | B7: =COUNTIFS(Results!$B$5:$B$5004,$A7,Results!$N$5:$N$5004,"<>SKIPPED") -> 0 | C7: =COUNTIFS(Results!$B$5:$B$5004,$A7,Results!$N$5:$N$5004,"PASS") -> 0 | D7: =B7-C7 -> 0 | E7: =COUNTIFS(Results!$B$5:$B$5004,$A7,Results!$N$5:$N$5004,"SKIPPED") -> 0 | F7: =IFERROR(C7/B7,"–") -> – | G7: =IFERROR(AVERAGEIFS(Results!$H$5:$H$5004,Results!$B$5:$B$5004,$A7,Results!$E$5:$E$5004,"read",Results!$I$5:$I$5004,">0"),"–") -> – | H7: =IFERROR(AVERAGEIFS(Results!$H$5:$H$5004,Results!$B$5:$B$5004,$A7,Results!$E$5:$E$5004,"write",Results!$I$5:$I$5004,">0"),"–") -> –
A8: 10Gbps | B8: =COUNTIFS(Results!$B$5:$B$5004,$A8,Results!$N$5:$N$5004,"<>SKIPPED") -> 0 | C8: =COUNTIFS(Results!$B$5:$B$5004,$A8,Results!$N$5:$N$5004,"PASS") -> 0 | D8: =B8-C8 -> 0 | E8: =COUNTIFS(Results!$B$5:$B$5004,$A8,Results!$N$5:$N$5004,"SKIPPED") -> 0 | F8: =IFERROR(C8/B8,"–") -> – | G8: =IFERROR(AVERAGEIFS(Results!$H$5:$H$5004,Results!$B$5:$B$5004,$A8,Results!$E$5:$E$5004,"read",Results!$I$5:$I$5004,">0"),"–") -> – | H8: =IFERROR(AVERAGEIFS(Results!$H$5:$H$5004,Results!$B$5:$B$5004,$A8,Results!$E$5:$E$5004,"write",Results!$I$5:$I$5004,">0"),"–") -> –
A9: SFP Port | B9: =COUNTIFS(Results!$B$5:$B$5004,$A9,Results!$N$5:$N$5004,"<>SKIPPED") -> 0 | C9: =COUNTIFS(Results!$B$5:$B$5004,$A9,Results!$N$5:$N$5004,"PASS") -> 0 | D9: =B9-C9 -> 0 | E9: =COUNTIFS(Results!$B$5:$B$5004,$A9,Results!$N$5:$N$5004,"SKIPPED") -> 0 | F9: =IFERROR(C9/B9,"–") -> – | G9: =IFERROR(AVERAGEIFS(Results!$H$5:$H$5004,Results!$B$5:$B$5004,$A9,Results!$E$5:$E$5004,"read",Results!$I$5:$I$5004,">0"),"–") -> – | H9: =IFERROR(AVERAGEIFS(Results!$H$5:$H$5004,Results!$B$5:$B$5004,$A9,Results!$E$5:$E$5004,"write",Results!$I$5:$I$5004,">0"),"–") -> –
A10: 2.4GHz | B10: =COUNTIFS(Results!$B$5:$B$5004,$A10,Results!$N$5:$N$5004,"<>SKIPPED") -> 0 | C10: =COUNTIFS(Results!$B$5:$B$5004,$A10,Results!$N$5:$N$5004,"PASS") -> 0 | D10: =B10-C10 -> 0 | E10: =COUNTIFS(Results!$B$5:$B$5004,$A10,Results!$N$5:$N$5004,"SKIPPED") -> 0 | F10: =IFERROR(C10/B10,"–") -> – | G10: =IFERROR(AVERAGEIFS(Results!$H$5:$H$5004,Results!$B$5:$B$5004,$A10,Results!$E$5:$E$5004,"read",Results!$I$5:$I$5004,">0"),"–") -> – | H10: =IFERROR(AVERAGEIFS(Results!$H$5:$H$5004,Results!$B$5:$B$5004,$A10,Results!$E$5:$E$5004,"write",Results!$I$5:$I$5004,">0"),"–") -> –
A11: 5GHz | B11: =COUNTIFS(Results!$B$5:$B$5004,$A11,Results!$N$5:$N$5004,"<>SKIPPED") -> 0 | C11: =COUNTIFS(Results!$B$5:$B$5004,$A11,Results!$N$5:$N$5004,"PASS") -> 0 | D11: =B11-C11 -> 0 | E11: =COUNTIFS(Results!$B$5:$B$5004,$A11,Results!$N$5:$N$5004,"SKIPPED") -> 0 | F11: =IFERROR(C11/B11,"–") -> – | G11: =IFERROR(AVERAGEIFS(Results!$H$5:$H$5004,Results!$B$5:$B$5004,$A11,Results!$E$5:$E$5004,"read",Results!$I$5:$I$5004,">0"),"–") -> – | H11: =IFERROR(AVERAGEIFS(Results!$H$5:$H$5004,Results!$B$5:$B$5004,$A11,Results!$E$5:$E$5004,"write",Results!$I$5:$I$5004,">0"),"–") -> –
A12: 6GHz | B12: =COUNTIFS(Results!$B$5:$B$5004,$A12,Results!$N$5:$N$5004,"<>SKIPPED") -> 0 | C12: =COUNTIFS(Results!$B$5:$B$5004,$A12,Results!$N$5:$N$5004,"PASS") -> 0 | D12: =B12-C12 -> 0 | E12: =COUNTIFS(Results!$B$5:$B$5004,$A12,Results!$N$5:$N$5004,"SKIPPED") -> 0 | F12: =IFERROR(C12/B12,"–") -> – | G12: =IFERROR(AVERAGEIFS(Results!$H$5:$H$5004,Results!$B$5:$B$5004,$A12,Results!$E$5:$E$5004,"read",Results!$I$5:$I$5004,">0"),"–") -> – | H12: =IFERROR(AVERAGEIFS(Results!$H$5:$H$5004,Results!$B$5:$B$5004,$A12,Results!$E$5:$E$5004,"write",Results!$I$5:$I$5004,">0"),"–") -> –
A13: MLO | B13: =COUNTIFS(Results!$B$5:$B$5004,$A13,Results!$N$5:$N$5004,"<>SKIPPED") -> 0 | C13: =COUNTIFS(Results!$B$5:$B$5004,$A13,Results!$N$5:$N$5004,"PASS") -> 0 | D13: =B13-C13 -> 0 | E13: =COUNTIFS(Results!$B$5:$B$5004,$A13,Results!$N$5:$N$5004,"SKIPPED") -> 0 | F13: =IFERROR(C13/B13,"–") -> – | G13: =IFERROR(AVERAGEIFS(Results!$H$5:$H$5004,Results!$B$5:$B$5004,$A13,Results!$E$5:$E$5004,"read",Results!$I$5:$I$5004,">0"),"–") -> – | H13: =IFERROR(AVERAGEIFS(Results!$H$5:$H$5004,Results!$B$5:$B$5004,$A13,Results!$E$5:$E$5004,"write",Results!$I$5:$I$5004,">0"),"–") -> –
A16: BY USB FORMAT — file system on the drive
A17: USB Format | B17: Rounds Run | C17: Passed | D17: Failed | E17: Skipped | F17: Pass Rate | G17: Avg Read (MB/s) | H17: Avg Write (MB/s)
A18: FAT32 | B18: =COUNTIFS(Results!$D$5:$D$5004,$A18,Results!$N$5:$N$5004,"<>SKIPPED") -> 0 | C18: =COUNTIFS(Results!$D$5:$D$5004,$A18,Results!$N$5:$N$5004,"PASS") -> 0 | D18: =B18-C18 -> 0 | E18: =COUNTIFS(Results!$D$5:$D$5004,$A18,Results!$N$5:$N$5004,"SKIPPED") -> 0 | F18: =IFERROR(C18/B18,"–") -> – | G18: =IFERROR(AVERAGEIFS(Results!$H$5:$H$5004,Results!$D$5:$D$5004,$A18,Results!$E$5:$E$5004,"read",Results!$I$5:$I$5004,">0"),"–") -> – | H18: =IFERROR(AVERAGEIFS(Results!$H$5:$H$5004,Results!$D$5:$D$5004,$A18,Results!$E$5:$E$5004,"write",Results!$I$5:$I$5004,">0"),"–") -> –
A19: NTFS | B19: =COUNTIFS(Results!$D$5:$D$5004,$A19,Results!$N$5:$N$5004,"<>SKIPPED") -> 0 | C19: =COUNTIFS(Results!$D$5:$D$5004,$A19,Results!$N$5:$N$5004,"PASS") -> 0 | D19: =B19-C19 -> 0 | E19: =COUNTIFS(Results!$D$5:$D$5004,$A19,Results!$N$5:$N$5004,"SKIPPED") -> 0 | F19: =IFERROR(C19/B19,"–") -> – | G19: =IFERROR(AVERAGEIFS(Results!$H$5:$H$5004,Results!$D$5:$D$5004,$A19,Results!$E$5:$E$5004,"read",Results!$I$5:$I$5004,">0"),"–") -> – | H19: =IFERROR(AVERAGEIFS(Results!$H$5:$H$5004,Results!$D$5:$D$5004,$A19,Results!$E$5:$E$5004,"write",Results!$I$5:$I$5004,">0"),"–") -> –
A20: exFAT | B20: =COUNTIFS(Results!$D$5:$D$5004,$A20,Results!$N$5:$N$5004,"<>SKIPPED") -> 0 | C20: =COUNTIFS(Results!$D$5:$D$5004,$A20,Results!$N$5:$N$5004,"PASS") -> 0 | D20: =B20-C20 -> 0 | E20: =COUNTIFS(Results!$D$5:$D$5004,$A20,Results!$N$5:$N$5004,"SKIPPED") -> 0 | F20: =IFERROR(C20/B20,"–") -> – | G20: =IFERROR(AVERAGEIFS(Results!$H$5:$H$5004,Results!$D$5:$D$5004,$A20,Results!$E$5:$E$5004,"read",Results!$I$5:$I$5004,">0"),"–") -> – | H20: =IFERROR(AVERAGEIFS(Results!$H$5:$H$5004,Results!$D$5:$D$5004,$A20,Results!$E$5:$E$5004,"write",Results!$I$5:$I$5004,">0"),"–") -> –
A21: HFS+ | B21: =COUNTIFS(Results!$D$5:$D$5004,$A21,Results!$N$5:$N$5004,"<>SKIPPED") -> 0 | C21: =COUNTIFS(Results!$D$5:$D$5004,$A21,Results!$N$5:$N$5004,"PASS") -> 0 | D21: =B21-C21 -> 0 | E21: =COUNTIFS(Results!$D$5:$D$5004,$A21,Results!$N$5:$N$5004,"SKIPPED") -> 0 | F21: =IFERROR(C21/B21,"–") -> – | G21: =IFERROR(AVERAGEIFS(Results!$H$5:$H$5004,Results!$D$5:$D$5004,$A21,Results!$E$5:$E$5004,"read",Results!$I$5:$I$5004,">0"),"–") -> – | H21: =IFERROR(AVERAGEIFS(Results!$H$5:$H$5004,Results!$D$5:$D$5004,$A21,Results!$E$5:$E$5004,"write",Results!$I$5:$I$5004,">0"),"–") -> –
A22: EXT4 | B22: =COUNTIFS(Results!$D$5:$D$5004,$A22,Results!$N$5:$N$5004,"<>SKIPPED") -> 0 | C22: =COUNTIFS(Results!$D$5:$D$5004,$A22,Results!$N$5:$N$5004,"PASS") -> 0 | D22: =B22-C22 -> 0 | E22: =COUNTIFS(Results!$D$5:$D$5004,$A22,Results!$N$5:$N$5004,"SKIPPED") -> 0 | F22: =IFERROR(C22/B22,"–") -> – | G22: =IFERROR(AVERAGEIFS(Results!$H$5:$H$5004,Results!$D$5:$D$5004,$A22,Results!$E$5:$E$5004,"read",Results!$I$5:$I$5004,">0"),"–") -> – | H22: =IFERROR(AVERAGEIFS(Results!$H$5:$H$5004,Results!$D$5:$D$5004,$A22,Results!$E$5:$E$5004,"write",Results!$I$5:$I$5004,">0"),"–") -> –
A25: BY FILE — transfer size
A26: File | B26: Rounds Run | C26: Passed | D26: Failed | E26: Skipped | F26: Pass Rate | G26: Avg Read (MB/s) | H26: Avg Write (MB/s) | I26: Chart Label
A27: small_1mb.bin | B27: =COUNTIFS(Results!$F$5:$F$5004,$A27,Results!$N$5:$N$5004,"<>SKIPPED") -> 0 | C27: =COUNTIFS(Results!$F$5:$F$5004,$A27,Results!$N$5:$N$5004,"PASS") -> 0 | D27: =B27-C27 -> 0 | E27: =COUNTIFS(Results!$F$5:$F$5004,$A27,Results!$N$5:$N$5004,"SKIPPED") -> 0 | F27: =IFERROR(C27/B27,"–") -> – | G27: =IFERROR(AVERAGEIFS(Results!$H$5:$H$5004,Results!$F$5:$F$5004,$A27,Results!$E$5:$E$5004,"read",Results!$I$5:$I$5004,">0"),"–") -> – | H27: =IFERROR(AVERAGEIFS(Results!$H$5:$H$5004,Results!$F$5:$F$5004,$A27,Results!$E$5:$E$5004,"write",Results!$I$5:$I$5004,">0"),"–") -> – | I27: 1 MB
A28: document_10mb.bin | B28: =COUNTIFS(Results!$F$5:$F$5004,$A28,Results!$N$5:$N$5004,"<>SKIPPED") -> 0 | C28: =COUNTIFS(Results!$F$5:$F$5004,$A28,Results!$N$5:$N$5004,"PASS") -> 0 | D28: =B28-C28 -> 0 | E28: =COUNTIFS(Results!$F$5:$F$5004,$A28,Results!$N$5:$N$5004,"SKIPPED") -> 0 | F28: =IFERROR(C28/B28,"–") -> – | G28: =IFERROR(AVERAGEIFS(Results!$H$5:$H$5004,Results!$F$5:$F$5004,$A28,Results!$E$5:$E$5004,"read",Results!$I$5:$I$5004,">0"),"–") -> – | H28: =IFERROR(AVERAGEIFS(Results!$H$5:$H$5004,Results!$F$5:$F$5004,$A28,Results!$E$5:$E$5004,"write",Results!$I$5:$I$5004,">0"),"–") -> – | I28: 10 MB
A29: image_50mb.bin | B29: =COUNTIFS(Results!$F$5:$F$5004,$A29,Results!$N$5:$N$5004,"<>SKIPPED") -> 0 | C29: =COUNTIFS(Results!$F$5:$F$5004,$A29,Results!$N$5:$N$5004,"PASS") -> 0 | D29: =B29-C29 -> 0 | E29: =COUNTIFS(Results!$F$5:$F$5004,$A29,Results!$N$5:$N$5004,"SKIPPED") -> 0 | F29: =IFERROR(C29/B29,"–") -> – | G29: =IFERROR(AVERAGEIFS(Results!$H$5:$H$5004,Results!$F$5:$F$5004,$A29,Results!$E$5:$E$5004,"read",Results!$I$5:$I$5004,">0"),"–") -> – | H29: =IFERROR(AVERAGEIFS(Results!$H$5:$H$5004,Results!$F$5:$F$5004,$A29,Results!$E$5:$E$5004,"write",Results!$I$5:$I$5004,">0"),"–") -> – | I29: 50 MB
A30: video_100mb.bin | B30: =COUNTIFS(Results!$F$5:$F$5004,$A30,Results!$N$5:$N$5004,"<>SKIPPED") -> 0 | C30: =COUNTIFS(Results!$F$5:$F$5004,$A30,Results!$N$5:$N$5004,"PASS") -> 0 | D30: =B30-C30 -> 0 | E30: =COUNTIFS(Results!$F$5:$F$5004,$A30,Results!$N$5:$N$5004,"SKIPPED") -> 0 | F30: =IFERROR(C30/B30,"–") -> – | G30: =IFERROR(AVERAGEIFS(Results!$H$5:$H$5004,Results!$F$5:$F$5004,$A30,Results!$E$5:$E$5004,"read",Results!$I$5:$I$5004,">0"),"–") -> – | H30: =IFERROR(AVERAGEIFS(Results!$H$5:$H$5004,Results!$F$5:$F$5004,$A30,Results!$E$5:$E$5004,"write",Results!$I$5:$I$5004,">0"),"–") -> – | I30: 100 MB
A31: large_500mb.bin | B31: =COUNTIFS(Results!$F$5:$F$5004,$A31,Results!$N$5:$N$5004,"<>SKIPPED") -> 0 | C31: =COUNTIFS(Results!$F$5:$F$5004,$A31,Results!$N$5:$N$5004,"PASS") -> 0 | D31: =B31-C31 -> 0 | E31: =COUNTIFS(Results!$F$5:$F$5004,$A31,Results!$N$5:$N$5004,"SKIPPED") -> 0 | F31: =IFERROR(C31/B31,"–") -> – | G31: =IFERROR(AVERAGEIFS(Results!$H$5:$H$5004,Results!$F$5:$F$5004,$A31,Results!$E$5:$E$5004,"read",Results!$I$5:$I$5004,">0"),"–") -> – | H31: =IFERROR(AVERAGEIFS(Results!$H$5:$H$5004,Results!$F$5:$F$5004,$A31,Results!$E$5:$E$5004,"write",Results!$I$5:$I$5004,">0"),"–") -> – | I31: 500 MB
A34: BY DUT ROLE — Router vs Extender
A35: DUT Role | B35: Rounds Run | C35: Passed | D35: Failed | E35: Skipped | F35: Pass Rate | G35: Avg Read (MB/s) | H35: Avg Write (MB/s)
A36: Router | B36: =COUNTIFS(Results!$A$5:$A$5004,$A36,Results!$N$5:$N$5004,"<>SKIPPED") -> 0 | C36: =COUNTIFS(Results!$A$5:$A$5004,$A36,Results!$N$5:$N$5004,"PASS") -> 0 | D36: =B36-C36 -> 0 | E36: =COUNTIFS(Results!$A$5:$A$5004,$A36,Results!$N$5:$N$5004,"SKIPPED") -> 0 | F36: =IFERROR(C36/B36,"–") -> – | G36: =IFERROR(AVERAGEIFS(Results!$H$5:$H$5004,Results!$A$5:$A$5004,$A36,Results!$E$5:$E$5004,"read",Results!$I$5:$I$5004,">0"),"–") -> – | H36: =IFERROR(AVERAGEIFS(Results!$H$5:$H$5004,Results!$A$5:$A$5004,$A36,Results!$E$5:$E$5004,"write",Results!$I$5:$I$5004,">0"),"–") -> –
A37: Extender | B37: =COUNTIFS(Results!$A$5:$A$5004,$A37,Results!$N$5:$N$5004,"<>SKIPPED") -> 0 | C37: =COUNTIFS(Results!$A$5:$A$5004,$A37,Results!$N$5:$N$5004,"PASS") -> 0 | D37: =B37-C37 -> 0 | E37: =COUNTIFS(Results!$A$5:$A$5004,$A37,Results!$N$5:$N$5004,"SKIPPED") -> 0 | F37: =IFERROR(C37/B37,"–") -> – | G37: =IFERROR(AVERAGEIFS(Results!$H$5:$H$5004,Results!$A$5:$A$5004,$A37,Results!$E$5:$E$5004,"read",Results!$I$5:$I$5004,">0"),"–") -> – | H37: =IFERROR(AVERAGEIFS(Results!$H$5:$H$5004,Results!$A$5:$A$5004,$A37,Results!$E$5:$E$5004,"write",Results!$I$5:$I$5004,">0"),"–") -> –
A40: BY CONNECTION — wired vs wireless
A41: Connection | B41: Rounds Run | C41: Passed | D41: Failed | E41: Skipped | F41: Pass Rate | G41: Avg Read (MB/s) | H41: Avg Write (MB/s)
A42: wired | B42: =COUNTIFS(Results!$C$5:$C$5004,$A42,Results!$N$5:$N$5004,"<>SKIPPED") -> 0 | C42: =COUNTIFS(Results!$C$5:$C$5004,$A42,Results!$N$5:$N$5004,"PASS") -> 0 | D42: =B42-C42 -> 0 | E42: =COUNTIFS(Results!$C$5:$C$5004,$A42,Results!$N$5:$N$5004,"SKIPPED") -> 0 | F42: =IFERROR(C42/B42,"–") -> – | G42: =IFERROR(AVERAGEIFS(Results!$H$5:$H$5004,Results!$C$5:$C$5004,$A42,Results!$E$5:$E$5004,"read",Results!$I$5:$I$5004,">0"),"–") -> – | H42: =IFERROR(AVERAGEIFS(Results!$H$5:$H$5004,Results!$C$5:$C$5004,$A42,Results!$E$5:$E$5004,"write",Results!$I$5:$I$5004,">0"),"–") -> –
A43: wireless | B43: =COUNTIFS(Results!$C$5:$C$5004,$A43,Results!$N$5:$N$5004,"<>SKIPPED") -> 0 | C43: =COUNTIFS(Results!$C$5:$C$5004,$A43,Results!$N$5:$N$5004,"PASS") -> 0 | D43: =B43-C43 -> 0 | E43: =COUNTIFS(Results!$C$5:$C$5004,$A43,Results!$N$5:$N$5004,"SKIPPED") -> 0 | F43: =IFERROR(C43/B43,"–") -> – | G43: =IFERROR(AVERAGEIFS(Results!$H$5:$H$5004,Results!$C$5:$C$5004,$A43,Results!$E$5:$E$5004,"read",Results!$I$5:$I$5004,">0"),"–") -> – | H43: =IFERROR(AVERAGEIFS(Results!$H$5:$H$5004,Results!$C$5:$C$5004,$A43,Results!$E$5:$E$5004,"write",Results!$I$5:$I$5004,">0"),"–") -> –
A46: OUTCOME — every round that was planned
A47: Outcome | B47: Rounds
A48: Passed | B48: =COUNTIF(Results!$N$5:$N$5004,"PASS") -> 0
A49: Failed | B49: =COUNTA(Results!$N$5:$N$5004)-COUNTIF(Results!$N$5:$N$5004,"SKIPPED")-B48 -> 0
A50: Skipped | B50: =COUNTIF(Results!$N$5:$N$5004,"SKIPPED") -> 0
A53: PER ROUND — average across every file, interface and format
...

Sheet Notes
B1: NOTES — HOW TO READ THIS WORKBOOK
B3: USING THIS TEMPLATE
B4: 1. Results sheet | C4: Enter one row per test round (one file, one direction, one round). Fill in the columns up to 'Failure Reason'; the grouped columns after it (time, SSID, firmware...) are optional traceability data.
B5: 2. Summary sheet | C5: Fill in the yellow cells: project, date, topology, client and devices under test. The totals, tiles and charts update by themselves from the Results sheet.
B6: 3. Analysis sheet | C6: The label in the first column of each table (e.g. '5GHz', 'NTFS') is what gets counted. Change or add labels there if your test uses different interfaces, formats or files.
B7: 4. Result column | C7: Use PASS, PERF_FAIL, ERROR or SKIPPED. Skipped rounds are counted separately, never as zero speed.
B8: 5. Issues sheet | C8: Copy failed, skipped or abnormal rounds here, or filter the Results sheet by Result.
B10: SHEETS
B11: Summary | C11: One-page dashboard: overall result, headline numbers, charts, test environment and devices under test.
B12: Results | C12: Every test round, one per row, with filters. Rows are tinted by outcome and the bar in the throughput column shows speed at a glance.
B13: Issues | C13: Only the rounds that failed, were skipped or looked abnormal, with the reason.
B14: Analysis | C14: The tables behind the charts: averages, pass rates and counts by interface, USB format, file, role and connection.
B16: RESULT CODES
B17: PASS | C17: The round ran and met the throughput threshold.
B18: PERF_FAIL | C18: The round ran but was slower than the threshold.
B19: ERROR | C19: The round could not complete (timeout, share error, no space...). The reason is in 'Failure Reason'.
B20: SKIPPED | C20: Not tested at all (a band couldn't be joined, or the USB share wasn't reachable). Never counted as 0 MB/s.
B22: HOW THE NUMBERS WORK
B23: Overall result | C23: FAIL if any round failed or errored. INCOMPLETE if nothing failed but something was skipped. PASS otherwise.
B24: Averages | C24: Read and write averages only include rounds that actually ran; skipped and errored rounds are left out.
B25: Pass rate | C25: Passed rounds divided by rounds that ran.
B26: Thresholds | C26: Each round is judged against the pass thresholds listed on the Summary sheet. Very small files finish so quickly that connection overhead dominates, so they miss speed thresholds more often than large files.
B28: Generated 2026-10-06 19:45 by the USB Performance Automation Tool
